Workbook

Sheet Framework_Overview
A1: ESG Rating Framework
A2: A simplified, transparent ESG scoring methodology for Indian textile & apparel manufacturers
A4: 1. Purpose
A5: This framework produces a transparent, defensible ESG score (0-100) for a peer set of 15 Indian textile and apparel manufacturers, using only company-disclosed data (BRSR filings, sustainability reports, and integrated annual reports). It is built for clarity: every score can be traced back to a single disclosed data point and a single, simple formula.
A7: 2. Scoring Process
A8: Raw Data (LS_Main_Dataset) -> Metric Score (0-100, one score per metric) -> Dimension Score (simple average of that dimension's metric scores) -> Overall ESG Score (weighted average of the four dimension scores) -> ESG Rating band. There is no criterion-level weighting and no multi-stage sub-scoring - every dimension score is a plain average of its metrics.
A10: 3. Dimension Weights
A11: Dimension | B11: Weight | C11: Metrics
A12: Environmental (E) | B12: 40% | C12: 7 metrics, simple average
A13: Social (S) | B13: 25% | C13: 2 metrics, simple average
A14: Governance (G) | B14: 20% | C14: 1 metrics, simple average
A15: Transparency (T) | B15: 15% | C15: 2 metrics, simple average
A16: Overall ESG Score = (Environmental x 40%) + (Social x 25%) + (Governance x 20%) + (Transparency x 15%)
A18: 4. Metrics Used
A19: Dimension | B19: Metric | C19: Direction | D19: Scoring Method
A20: Environmental | B20: Emissions Intensity (tCO2e/employee) | C20: Lower better | D20: Peer min-max
B21: Renewable Energy % | C21: Higher better | D21: Direct value
B22: Water Intensity (KL/employee) | C22: Lower better | D22: Peer min-max
B23: Waste Intensity (MT/employee) | C23: Lower better | D23: Peer min-max
B24: Sustainable Materials % | C24: Higher better | D24: Direct value
B25: SBTi Status | C25: Higher better | D25: Fixed tier lookup
B26: RE100 Membership | C26: Higher better | D26: Binary (Yes/No)
A27: Social | B27: Gender Diversity (Female %) | C27: Higher better | D27: Direct value
B28: Farmer/Smallholder Engagement | C28: Higher better | D28: Binary (disclosed/not)
A29: Governance | B29: Ownership Type (Public/Private) | C29: Higher better | D29: Fixed tier lookup
A30: Transparency | B30: Reporting Framework Count | C30: Higher better | D30: Auto-counted + tier
B31: CDP Disclosure Score | C31: Higher better | D31: Fixed tier lookup
A33: 5. Rating Scale
A34: Overall ESG Score | B34: Rating
A35: >= 90 | B35: AAA
A36: 80 - 89.9 | B36: AA
A37: 70 - 79.9 | B37: A
A38: 60 - 69.9 | B38: BBB
A39: 50 - 59.9 | B39: BB
A40: 40 - 49.9 | B40: B
A41: < 40 | B41: CCC
A43: 6. Confidence Score
A44: Data Coverage % = share of the 12 scored metrics with a usable disclosed value for that company. Banded as High (>=80%), Medium (60-79.9%), Low (<60%). This flags how much disclosed evidence backs a company's score, independent of the score's value.
A46: 7. Data Sources
A47: All data is drawn from company-disclosed sources (BRSR filings, sustainability reports, integrated annual reports) for each company's most recent available reporting year (FY2023-24 or FY2024-25). No third-party verification was performed beyond each company's own disclosed CDP/assurance status.
...

Sheet LS_Main_Dataset
A1: Company Name | B1: HQ City | C1: HQ State | D1: Latitude | E1: Longitude | F1: Year Founded | G1: Ownership Type | H1: Num Employees | I1: Num Male Workers | J1: Male % | K1: Female | L1: Female % | M1: Num Facilities | N1: Reporting Standard | O1: Reporting FY | P1: Scope1 tCO2e | Q1: Scope2 LocationBased tCO2e | R1: Scope1 Plus 2 tCO2e | S1: RE Percentage | T1: Total Energy TJ | U1: Solar Capacity MWp | V1: Total Water KL | W1: ZLD Coverage % | X1: SBTi Status | Y1: SBTi Engagement Opp | Z1: CDP Score | AA1: ISO14001 | AB1: GOTS | AC1: RE100 Member | AD1: Sustainable Materials / Inputs % | AE1: Farmers Engaged | AF1: Total Waste Generated (MT) | AG1: Hazardous Waste (MT | AH1: Plastic Waste (MT) | AI1: Renewable Energy Target | AJ1: Coal Phase-Out Status | AK1: Major Buyers | AL1: Primary Raw Material | AM1: Fabric Sourcing Geography | AN1: Employee Carbon Intensity (tCO₂e/employee/year) | AO1: Energy Carbon Intensity (tCO₂e/TJ) | AP1: Environmental (40%) | AQ1: Social (25%) | AR1: Governance (20%) | AS1: Transparency (15%) | AT1: Overall ESG Score | AU1: ESG Rating | AV1: Data Coverage %
A2: Shahi Exports | B2: Faridabad | C2: Haryana | D2: 28.4089 | E2: 77.3178 | F2: 1974 | G2: Private | H2: 104340 | I2: 29582 | J2: =ROUND((I2/H2)*100,2) -> 28.35 | K2: 74751 | L2: =ROUND((K2/H2)*100,2) -> 71.64 | M2: 52 | N2: Sustainability Report | O2: FY2023-24 | P2: 382577 | Q2: 57186 | R2: 439763 | S2: 65 | T2: 4334.23 | U2: 84 | V2: 4828552 | W2: Not Disclosed | X2: Not a member | Y2: HIGH | Z2: B | AA2: Certified | AB2: Certified | AC2: No | AD2: 50 | AF2: 52614 | AI2: 100% RE by FY27 | AJ2: 100% coal-free in garmenting | AK2: Walmart, Gap Inc., Target, H&M, Nike, Uniqlo, PVH, Abercrombie & Fitch, C&A, Calvin Klein, Columbia Sportswear, Inditex, Kohl's | AL2: Cotton Fabric, Polyester Fabric, Viscose, Denim, Trims | AM2: India + China + Bangladesh + Vietnam + Turkey | AN2: =IFERROR(ROUND(R2/H2, 2), "") -> 4.21 | AO2: =IFERROR(ROUND(R2/T2, 2), "") -> 101.46 | AP2: =ROUND(Calculations!N2,1) -> 60.8 | AQ2: =ROUND(Calculations!Q2,1) -> 71.6 | AR2: =ROUND(Calculations!R2,1) -> 55 | AS2: =ROUND(Calculations!V2,1) -> 52.5 | AT2: =ROUND(Calculations!W2,1) -> 61.1 | AU2: =Calculations!X2 -> BBB | AV2: =ROUND(Calculations!Y2,0) -> 92
A3: Vardhman Textiles | B3: Ludhiana | C3: Punjab | D3: 30.901 | E3: 75.8573 | F3: 1965 | G3: Public Listed | H3: 27956 | I3: 18345 | J3: =ROUND((I3/H3)*100,2) -> 65.62 | K3: 9611 | L3: =ROUND((K3/H3)*100,2) -> 34.38 | M3: 15 | N3: BRSR | O3: FY2023-24 | P3: 282924 | Q3: 857272.48 | R3: 1140196.5 | S3: 14.46 | T3: 12928 | U3: 19.2 | V3: 5695455 | W3: Not Disclosed | X3: Not found | Y3: HIGH | AA3: Certified | AB3: Certified | AC3: No | AD3: 28 | AF3: 21423.87 | AG3: 12459.58 | AH3: 1264.35 | AI3: 53 MW solar capacity by 2025 | AJ3: Transitioning boilers to biomass | AK3: H&M, Gap, Banana Republic, Old Navy, Esprit, Benetton, Ford (special steels) | AL3: Lint Cotton (primary), Organic Cotton, Better Cotton, Man-made Fibres | AM3: India (Punjab, HP, MP) + limited global specialty fibres | AN3: =IFERROR(ROUND(R3/H3, 2), "") -> 40.79 | AO3: =IFERROR(ROUND(R3/T3, 2), "") -> 88.2 | AP3: =ROUND(Calculations!N3,1) -> 47.4 | AQ3: =ROUND(Calculations!Q3,1) -> 34.4 | AR3: =ROUND(Calculations!R3,1) -> 100 | AS3: =ROUND(Calculations!V3,1) -> 30 | AT3: =ROUND(Calculations!W3,1) -> 52.1 | AU3: =Calculations!X3 -> BB | AV3: =ROUND(Calculations!Y3,0) -> 83
A4: Arvind Limited | B4: Ahmedabad | C4: Gujarat | D4: 23.0225 | E4: 72.5714 | F4: 1931 | G4: Public Listed | H4: 33311 | I4: 23280 | J4: =ROUND((I4/H4)*100,2) -> 69.89 | K4: 10031 | L4: =ROUND((K4/H4)*100,2) -> 30.11 | M4: 12 | N4: BRSR + Integrated Annual Report | O4: FY2024-25 | P4: 253283 | Q4: 190808 | R4: 444091 | S4: 37 | T4: 6187.58 | V4: 2645994 | W4: 83.33 | X4: Committed | Y4: MEDIUM | AA4: Certified | AB4: Certified | AC4: No | AD4: 37 | AE4: 12000 | AF4: 34493 | AG4: 11765 | AH4: 762.2 | AI4: 40% RE by 2025 | AJ4: Biomass replacing coal | AK4: Levi's, Gap Inc., H&M, American Eagle, Inditex, VF Corporation, Marks & Spencer, Calvin Klein, Hugo Boss, J.Crew, Mango, Banana Republic | AL4: Cotton (BCI certified), Organic Cotton, Linen, Viscose, Modal, Tencel | AM4: India: Gujarat (Ahmedabad, Naroda, Santej) + Bangladesh facility | AN4: =IFERROR(ROUND(R4/H4, 2), "") -> 13.33 | AO4: =IFERROR(ROUND(R4/T4, 2), "") -> 71.77 | AP4: =ROUND(Calculations!N4,1) -> 66.5 | AQ4: =ROUND(Calculations!Q4,1) -> 65.1 | AR4: =ROUND(Calculations!R4,1) -> 100 | AS4: =ROUND(Calculations!V4,1) -> 50 | AT4: =ROUND(Calculations!W4,1) -> 70.4 | AU4: =Calculations!X4 -> A | AV4: =ROUND(Calculations!Y4,0) -> 92
A5: Trident Limited | B5: Barnala | C5: Punjab | D5: 30.3819 | E5: 75.5468 | F5: 1990 | G5: Public Listed | H5: 15647 | I5: 12850 | J5: =ROUND((I5/H5)*100,2) -> 82.12 | K5: 2797 | L5: =ROUND((K5/H5)*100,2) -> 17.88 | M5: 15 | N5: GRI + TCFD + UNGC + SASB + BRSR | O5: FY2023-24 | P5: 671774 | Q5: 347698 | R5: 1019472 | S5: 34.9 | T5: 10157 | U5: 40.9 | V5: 13724529 | W5: Not Disclosed | X5: Committed | Y5: LOW-MEDIUM | AA5: Certified | AB5: Certified | AC5: No | AD5: 38.5 | AF5: 251613 | AG5: 4841 | AH5: 606 | AI5: 50% eng mix from RE (FY25) | AJ5: 41.3% biomass in fuel mix | AK5: Ralph Lauren, Calvin Klein, JC Penney, IKEA, Target, Walmart, Macy's, Kohl's, Sam's Club, Burlington | AL5: Cotton (BCI certified), Wheat Straw (paper), Yarn | AM5: India: 95% domestic; Punjab + Madhya Pradesh (Barnala, Dhaula, Budhni) | AN5: =IFERROR(ROUND(R5/H5, 2), "") -> 65.15 | AO5: =IFERROR(ROUND(R5/T5, 2), "") -> 100.37 | AP5: =ROUND(Calculations!N5,1) -> 53 | AQ5: =ROUND(Calculations!Q5,1) -> 17.9 | AR5: =ROUND(Calculations!R5,1) -> 100 | AS5: =ROUND(Calculations!V5,1) -> 92 | AT5: =ROUND(Calculations!W5,1) -> 59.5 | AU5: =Calculations!X5 -> BB | AV5: =ROUND(Calculations!Y5,0) -> 83
A6: K.P.R. Mill Limited | B6: Coimbatore | C6: Tamil Nadu | D6: 11.0168 | E6: 76.9558 | F6: 2003 | G6: Public Listed | H6: 20774 | I6: 3403 | J6: =ROUND((I6/H6)*100,2) -> 16.38 | K6: 17371 | L6: =ROUND((K6/H6)*100,2) -> 83.62 | M6: 12 | N6: BRSR | O6: FY2023-24 | P6: 59833.96 | Q6: 161703.12 | R6: 221537.08 | S6: 24.1 | T6: 1741.85 | U6: 34 | V6: 1842246.6 | W6: 100 | X6: Not Committed | Y6: HIGH | AA6: Certified | AB6: Certified | AC6: No | AD6: 40 | AF6: 1828.4 | AG6: 79.8 | AH6: 22.8 | AI6: 33% of power from solar | AJ6: Not Disclosed | AK6: Primark, Walmart, H&M, Marks & Spencer, ASDA, K-Mart | AL6: Cotton (major), Organic Cotton, Viscose | AM6: India (mainly South & West India) | AN6: =IFERROR(ROUND(R6/H6, 2), "") -> 10.66 | AO6: =IFERROR(ROUND(R6/T6, 2), "") -> 127.18 | AP6: =ROUND(Calculations!N6,1) -> 56.6 | AQ6: =ROUND(Calculations!Q6,1) -> 83.6 | AR6: =ROUND(Calculations!R6,1) -> 100 | AS6: =ROUND(Calculations!V6,1) -> 30 | AT6: =ROUND(Calculations!W6,1) -> 68 | AU6: =Calculations!X6 -> BBB | AV6: =ROUND(Calculations!Y6,0) -> 83
A7: Page Industries | B7: Bengaluru | C7: Karnataka | D7: 12.9716 | E7: 77.5946 | F7: 1994 | G7: Public Listed | H7: 20658 | I7: 4271 | J7: =ROUND((I7/H7)*100,2) -> 20.67 | K7: 16387 | L7: =ROUND((K7/H7)*100,2) -> 79.33 | M7: 23 | N7: GRI 2021 + SASB + UNGC + BRSR | O7: FY2024-25 | P7: 993 | Q7: 11945 | R7: 12938 | S7: 33 | T7: 108.71 | U7: 0 | V7: 175630 | W7: 50 | X7: Not Committed | Y7: MEDIUM | AA7: Certified | AB7: Not Certified | AC7: No | AD7: 82 | AF7: 6204.84 | AG7: 68.09 | AH7: 1308 | AI7: 50% RE by FY28 | AJ7: Coal-free | AK7: Jockey International, Speedo, India retail | AL7: Cotton fabric, elastic, yarn (OEKO-TEX 100%); ECONYL + REPET recycled yarn for Speedo | AM7: India — Tirupur + Karnataka (domestic only) | AN7: =IFERROR(ROUND(R7/H7, 2), "") -> 0.63 | AO7: =IFERROR(ROUND(R7/T7, 2), "") -> 119.01 | AP7: =ROUND(Calculations!N7,1) -> 64.9 | AQ7: =ROUND(Calculations!Q7,1) -> 79.3 | AR7: =ROUND(Calculations!R7,1) -> 100 | AS7: =ROUND(Calculations!V7,1) -> 80 | AT7: =ROUND(Calculations!W7,1) -> 77.8 | AU7: =Calculations!X7 -> A | AV7: =ROUND(Calculations!Y7,0) -> 83
A8: Indo Count | B8: Maharashtra | C8: Mumbai | D8: 18.922 | E8: 72.8231 | F8: 1988 | G8: Public Listed | H8: 7442 | I8: 6324 | J8: =ROUND((I8/H8)*100,2) -> 84.98 | K8: 1118 | L8: =ROUND((K8/H8)*100,2) -> 15.02 | M8: 7 | N8: GRI Standards 2021 + SASB + TCFD | O8: FY2023-24 | P8: 185243 | Q8: 105108 | R8: 290351 | U8: 9.3 | W8: 25 | X8: Committed | Y8: LOW | Z8: B | AA8: Certified | AB8: Certified | AC8: No | AD8: 22 | AE8: 35805 | AF8: Not Disclosed | AG8: Not Disclosed | AH8: Not Disclosed | AI8: Net Zero by 2040 | AJ8: Reducing coal via efficiency measures | AK8: Walmart, Costco, Kohl's, Revman, JC Penney, Target | AL8: Cotton, Yarn, Fabric | AN8: =IFERROR(ROUND(R8/H8, 2), "") -> 39.02 | AO8: =IFERROR(ROUND(R8/T8, 2), "") | AP8: =ROUND(Calculations!N8,1) -> 54.9 | AQ8: =ROUND(Calculations!Q8,1) -> 57.5 | AR8: =ROUND(Calculations!R8,1) -> 100 | AS8: =ROUND(Calculations!V8,1) -> 70 | AT8: =ROUND(Calculations!W8,1) -> 66.8 | AU8: =Calculations!X8 -> BBB | AV8: =ROUND(Calculations!Y8,0) -> 75
A9: Pearl Global | B9: Gurugram | C9: Haryana | D9: 28.4595 | E9: 77.0266 | F9: 1989 | G9: Public Listed | H9: 10913 | I9: 5039 | J9: =ROUND((I9/H9)*100,2) -> 46.17 | K9: 5874 | L9: =ROUND((K9/H9)*100,2) -> 53.83 | M9: 10 | N9: BRSR | O9: FY2023-24 | P9: 25.77 | Q9: 7170.84 | R9: 7196.61 | T9: 28.62 | V9: 132734 | W9: Not Disclosed | X9: Not a member | Y9: HIGH | AA9: Certified | AB9: Certified | AC9: No | AD9: 24 | AF9: 1755.49 | AG9: 0.87 | AH9: 43.31 | AI9: Not Disclosed | AJ9: Not Disclosed | AK9: Gap, Kohl's, PVH Corp, Polo Ralph Lauren, Inditex, Target, Macy's, Belk, Walmart, Mango, Primark | AL9: Cotton, wool, silk, linen, georgette, polyester fabrics | AM9: India: 100% domestic; Bangladesh: 70% local + 30% China imports | AN9: =IFERROR(ROUND(R9/H9, 2), "") -> 0.66 | AO9: =IFERROR(ROUND(R9/T9, 2), "") -> 251.45 | AP9: =ROUND(Calculations!N9,1) -> 56.4 | AQ9: =ROUND(Calculations!Q9,1) -> 53.8 | AR9: =ROUND(Calculations!R9,1) -> 100 | AS9: =ROUND(Calculations!V9,1) -> 30 | AT9: =ROUND(Calculations!W9,1) -> 60.5 | AU9: =Calculations!X9 -> BBB | AV9: =ROUND(Calculations!Y9,0) -> 75
A10: Welspun Living | B10: Mumbai | C10: Maharashtra | D10: 18.9733 | E10: 72.8237 | F10: 1985 | G10: Public Listed | H10: 27719 | I10: 20128 | J10: =ROUND((I10/H10)*100,2) -> 72.61 | K10: 7591 | L10: =ROUND((K10/H10)*100,2) -> 27.39 | M10: 4 | N10: GRI + BRSR + SASB + TCFD + UNGC | O10: FY2024-25 | P10: 256451 | Q10: 465706 | R10: 722157 | S10: 30.54 | T10: 6361.34 | U10: 38.1 | V10: 5036970 | W10: Not Disclosed | X10: Committed | Y10: LOW | Z10: B | AA10: Certified | AB10: Via products | AC10: No | AD10: 76 | AE10: 29528 | AF10: 31517 | AG10: 1060 | AH10: 484 | AI10: 100% RE by FY30 | AJ10: Reducing coal via biomass substitution | AK10: Walmart, IKEA, Target, Costco, Kohl's, Amazon, JCPenney, Sheridan, Christy, Lifestyle | AL10: Cotton (BCI + Organic + Fair Trade); Recycled polyester (GRS) | AM10: Vertically integrated — own spinning, weaving + BCI farmer network | AN10: =IFERROR(ROUND(R10/H10, 2), "") -> 26.05 | AO10: =IFERROR(ROUND(R10/T10, 2), "") -> 113.52 | AP10: =ROUND(Calculations!N10,1) -> 69.7 | AQ10: =ROUND(Calculations!Q10,1) -> 63.7 | AR10: =ROUND(Calculations!R10,1) -> 100 | AS10: =ROUND(Calculations!V10,1) -> 83.5 | AT10: =ROUND(Calculations!W10,1) -> 76.3 | AU10: =Calculations!X10 -> A | AV10: =ROUND(Calculations!Y10,0) -> 100
A11: Siyaram's Silk Mills | B11: Mumbai | C11: Maharashtra | D11: 19.076 | E11: 72.8777 | F11: 1978 | G11: Public Listed | H11: 4103 | I11: 3339 | J11: =ROUND((I11/H11)*100,2) -> 81.38 | K11: 764 | L11: =ROUND((K11/H11)*100,2) -> 18.62 | M11: 13 | N11: BRSR (SEBI Regulation 34(2)(f)) | O11: FY2024-25 | P11: 50927 | Q11: 38875 | R11: 89802 | S11: 1.66 | T11: 1085.12 | U11: 5.392 | V11: 297892 | W11: Not Disclosed | X11: Not Committed | Y11: HIGH | AA11: Certified | AB11: Certified | AC11: No | AD11: 41.45 | AF11: 5507.59 | AH11: 100.14 | AI11: 15% electricity from RE by FY26 | AJ11: No formal phase-out date | AK11: NEXT, M&S, Calvin Klein, Perry Ellis, Target, Kenneth Cole, Express, Topman | AL11: Polyester-Viscose (PV), Cotton, Wool, Linen | AM11: India + Europe + Australia (premium fibres) | AN11: =IFERROR(ROUND(R11/H11, 2), "") -> 21.89 | AO11: =IFERROR(ROUND(R11/T11, 2), "") -> 82.76 | AP11: =ROUND(Calculations!N11,1) -> 53.5 | AQ11: =ROUND(Calculations!Q11,1) -> 18.6 | AR11: =ROUND(Calculations!R11,1) -> 100 | AS11: =ROUND(Calculations!V11,1) -> 30 | AT11: =ROUND(Calculations!W11,1) -> 50.5 | AU11: =Calculations!X11 -> BB | AV11: =ROUND(Calculations!Y11,0) -> 83
A12: Jindal Worldwide | B12: Ahmedabad | C12: Gujarat | D12: 23.0225 | E12: 72.5714 | F12: 1986 | G12: Public Listed | H12: 1412 | I12: 1393 | J12: =ROUND((I12/H12)*100,2) -> 98.65 | K12: 19 | L12: =ROUND((K12/H12)*100,2) -> 1.35 | M12: 5 | N12: BRSR | O12: FY2024-25 | P12: 147112.96 | Q12: 1076.67 | R12: 148189.63 | S12: 0.71 | T12: 181.46 | V12: 99137 | W12: 0 | X12: Not Committed | Y12: Not Disclosed | Z12: Not Disclosed | AA12: Not Certified | AB12: Certified | AC12: No | AD12: 0 | AF12: 207.81 | AG12: 182.06 | AH12: 6.37 | AI12: Not Disclosed | AJ12: No formal phase-out date (biomass replacing coal) | AK12: Not Disclosed (B2B - end-use industries; no specific brand names disclosed) | AL12: Cotton, Yarn (BCI, Organic, GRS-certified on request) | AM12: India (16 states, GST registered in 1 state) + exports to 24 countries | AN12: =IFERROR(ROUND(R12/H12, 2), "") -> 104.95 | AO12: =IFERROR(ROUND(R12/T12, 2), "") -> 816.65 | AP12: =ROUND(Calculations!N12,1) -> 46.9 | AQ12: =ROUND(Calculations!Q12,1) -> 1.4 | AR12: =ROUND(Calculations!R12,1) -> 100 | AS12: =ROUND(Calculations!V12,1) -> 15 | AT12: =ROUND(Calculations!W12,1) -> 41.4 | AU12: =Calculations!X12 -> B | AV12: =ROUND(Calculations!Y12,0) -> 92
A13: Grasim Industries | B13: Mumbai | C13: Maharashtra | D13: 19.0178 | E13: 72.8478 | F13: 1947 | G13: Public Listed | H13: 55257 | I13: 52605 | J13: =ROUND((I13/H13)*100,2) -> 95.2 | K13: 2652 | L13: =ROUND((K13/H13)*100,2) -> 4.8 | M13: 25 | N13: GRI + BRSR + TCFD + UNGC + SASB + Integrated Annual Report | O13: FY2024-25 | P13: 86219949 | Q13: 3095951 | R13: 89315900 | S13: 6.5 | T13: 423991.73 | V13: 63570000 | W13: 52 | X13: Not Committed | Y13: LOW | Z13: Not Disclosed | AA13: Certified | AB13: Not Certified | AC13: No | AD13: 62 | AF13: 3978444 | AI13: 16% renewable energy in total energy mix by FY30 | AJ13: No formal coal phase-out date | AK13: Paints (retail+B2B), Cellulosic Fibres (viscose/VSF), Chemicals (caustic soda, chlorine), Cement (via UltraTech) | AL13: Wood pulp (FSC/SFI/PEFC certified), Cotton (Textiles), Caustic soda inputs, Limestone (Cement) | AM13: India (multi-state: MP, Gujarat, Karnataka, Rajasthan, etc.) + International (Sri Lanka, UAE, Bangladesh) | AN13: =IFERROR(ROUND(R13/H13, 2), "") -> 1616.37 | AO13: =IFERROR(ROUND(R13/T13, 2), "") -> 210.65 | AP13: =ROUND(Calculations!N13,1) -> 15.5 | AQ13: =ROUND(Calculations!Q13,1) -> 4.8 | AR13: =ROUND(Calculations!R13,1) -> 100 | AS13: =ROUND(Calculations!V13,1) -> 50 | AT13: =ROUND(Calculations!W13,1) -> 34.9 | AU13: =Calculations!X13 -> CCC | AV13: =ROUND(Calculations!Y13,0) -> 92
A14: RSWM Limited | B14: Bhilwara (Gulabpura) | C14: Rajasthan | D14: 25.3407 | E14: 74.6364 | F14: 1960 | G14: Public Listed | H14: 17799 | I14: 15107 | J14: =ROUND((I14/H14)*100,2) -> 84.88 | K14: 2692 | L14: =ROUND((K14/H14)*100,2) -> 15.12 | M14: 22 | N14: BRSR + Sustainability Report | O14: FY2024-25 | P14: Not Disclosed | Q14: Not Disclosed | R14: Not Disclosed | S14: 33 | T14: 2807.4 | U14: 34.36 | V14: 18,83,332 | W14: 100 | X14: Not Disclosed | Y14: HIGH | Z14: Not Disclosed | AA14: Certified | AB14: Certified | AC14: No | AD14: 56.46 | AE14: Not Disclosed | AF14: 7985 | AG14: 2837.94 | AH14: 754.22 | AI14: 45% green energy (of total energy consumption) by FY26, up from 33% in FY25; all 6 industrial boilers on biofuel by FY26 (3 of 6 already converted); PET recycling capacity expansion 122→130 TPD | AJ14: No formal coal phase-out date disclosed; actively transitioning boilers from coal to biofuel (3 of 6 boilers converted as of FY25, target 100% by FY26) | AK14: Not Disclosed (B2B yarn/fabric manufacturer supplying fabric manufacturers, apparel brands & textile wholesalers across 70+ countries; no specific brand names disclosed) | AL14: Cotton, Synthetic/man-made fibres (polyester, viscose, PV blends), Recycled Polyester (from PET bottles), Organic Cotton | AM14: India — 12 plants across Rajasthan (Bhilwara, Banswara, Sikar/Ringas, Udaipur/Rishabdev) + Uttar Pradesh (Mathura/Chhata); exports ~31.47% of turnover to 63 countries | AN14: =IFERROR(ROUND(R14/H14, 2), "") | AO14: =IFERROR(ROUND(R14/T14, 2), "") | AP14: =ROUND(Calculations!N14,1) -> 37.8 | AQ14: =ROUND(Calculations!Q14,1) -> 7.6 | AR14: =ROUND(Calculations!R14,1) -> 100 | AS14: =ROUND(Calculations!V14,1) -> 25 | AT14: =ROUND(Calculations!W14,1) -> 40.8 | AU14: =Calculations!X14 -> B | AV14: =ROUND(Calculations!Y14,0) -> 83
A15: Gokaldas Exports Limited | B15: Bengaluru | C15: Karnataka | D15: 12.9716 | E15: 77.5946 | F15: 2004 | G15: Public Listed | H15: 40285 | I15: 11904 | J15: =ROUND((I15/H15)*100,2) -> 29.55 | K15: 28381 | L15: =ROUND((K15/H15)*100,2) -> 70.45 | M15: 36 | N15: BRSR (SEBI Regulation 34(2)(f)) | O15: FY2024-25 | P15: 41722 | Q15: Bengaluru | R15: 55952 | S15: 78.73 | T15: 503 | U15: 7.5 | V15: 468556 | W15: 100 | X15: Not Disclosed | Y15: HIGH | Z15: Not Disclosed | AA15: Not Disclosed | AB15: Certified | AC15: No | AD15: 13 | AE15: Not Disclosed | AF15: 5052 | AG15: 530.3 | AH15: 131 | AI15: Carbon neutral (own ops) & water positive by FY2030; Net-zero by 2045; Zero-to-landfill before FY2030; ~72-73% of grid electricity offset by 7.5 MW solar park (13 units) | AJ15: Not Disclosed (no coal mentioned; energy mix is grid electricity, biomass, and other non-renewable fuel) | AK15: Not Disclosed by name (global fashion retailers, wholesalers & brands, primarily USA & Europe; exports = 87% of turnover) | AL15: Fabric & Trims (predominantly cotton-based; 13% recycled fabric) | AM15: India (70.9% of inputs sourced domestically); remainder via customer(global brand)-nominated vendors globally | AN15: =IFERROR(ROUND(R15/H15, 2), "") -> 1.39 | AO15: =IFERROR(ROUND(R15/T15, 2), "") -> 111.24 | AP15: =ROUND(Calculations!N15,1) -> 55.9 | AQ15: =ROUND(Calculations!Q15,1) -> 35.2 | AR15: =ROUND(Calculations!R15,1) -> 100 | AS15: =ROUND(Calculations!V15,1) -> 15 | AT15: =ROUND(Calculations!W15,1) -> 53.4 | AU15: =Calculations!X15 -> BB | AV15: =ROUND(Calculations!Y15,0) -> 100
A16: Vamani Overseas Pvt. Ltd. | B16: Faridabad | C16: Haryana | D16: 28.4089 | E16: 77.3178 | F16: 2008 | G16: Private | H16: 11464 | I16: 5879 | J16: =ROUND((I16/H16)*100,2) -> 51.28 | K16: 5585 | L16: =ROUND((K16/H16)*100,2) -> 48.72 | M16: 8 | N16: GRI Standards 2021 (GRI 1, 2 & 3) | O16: CY2023 (Jan-Dec 2023) | P16: 2138 | Q16: 4799 | R16: 6937 | S16: 5.1 | T16: 35.58 | U16: 0.38 | V16: 82038 | W16: Not Disclosed | X16: Not Disclosed | Y16: HIGH | Z16: C | AA16: Certified | AB16: Certified | AC16: No | AD16: Not Disclosed | AF16: 483.26 | AG16: 4.47 | AH16: 3.45 | AI16: 80% renewable electricity by 2030 (vs. 2023 baseline) | AJ16: No coal disclosed; 100% PNG-fired boilers + biomass-fired boiler in Guntur plant | AK16: ZARA (Inditex), LEVI's, Mango, Kiabi, Target, C&A, H&M | AL16: Cotton (BCI/GOTS/OCS certified), Polyester (GRS/RCS certified), Viscose (Ecovera/Ecoliva), Flax/Linen (European Flax certified) | AM16: Not Disclosed | AN16: =IFERROR(ROUND(R16/H16, 2), "") -> 0.61 | AO16: =IFERROR(ROUND(R16/T16, 2), "") -> 194.97 | AP16: =ROUND(Calculations!N16,1) -> 50.9 | AQ16: =ROUND(Calculations!Q16,1) -> 48.7 | AR16: =ROUND(Calculations!R16,1) -> 55 | AS16: =ROUND(Calculations!V16,1) -> 40 | AT16: =ROUND(Calculations!W16,1) -> 49.5 | AU16: =Calculations!X16 -> B | AV16: =ROUND(Calculations!Y16,0) -> 83

Sheet ESG_Scorecard
A1: ESG Rating Scorecard
A2: Overall ESG Score = (Environmental x 40%) + (Social x 25%) + (Governance x 20%) + (Transparency x 15%)
A4: Company | B4: Environmental (40%) | C4: Social (25%) | D4: Governance (20%) | E4: Transparency (15%) | F4: Overall ESG Score | G4: ESG Rating | H4: Data Coverage % | I4: Confidence Level
A5: =Calculations!A2 -> Shahi Exports | B5: =ROUND(Calculations!N2,1) -> 60.8 | C5: =ROUND(Calculations!Q2,1) -> 71.6 | D5: =ROUND(Calculations!R2,1) -> 55 | E5: =ROUND(Calculations!V2,1) -> 52.5 | F5: =ROUND(Calculations!W2,1) -> 61.1 | G5: =Calculations!X2 -> BBB | H5: =ROUND(Calculations!Y2,0) -> 92 | I5: =Calculations!Z2 -> High
A6: =Calculations!A3 -> Vardhman Textiles | B6: =ROUND(Calculations!N3,1) -> 47.4 | C6: =ROUND(Calculations!Q3,1) -> 34.4 | D6: =ROUND(Calculations!R3,1) -> 100 | E6: =ROUND(Calculations!V3,1) -> 30 | F6: =ROUND(Calculations!W3,1) -> 52.1 | G6: =Calculations!X3 -> BB | H6: =ROUND(Calculations!Y3,0) -> 83 | I6: =Calculations!Z3 -> High
A7: =Calculations!A4 -> Arvind Limited | B7: =ROUND(Calculations!N4,1) -> 66.5 | C7: =ROUND(Calculations!Q4,1) -> 65.1 | D7: =ROUND(Calculations!R4,1) -> 100 | E7: =ROUND(Calculations!V4,1) -> 50 | F7: =ROUND(Calculations!W4,1) -> 70.4 | G7: =Calculations!X4 -> A | H7: =ROUND(Calculations!Y4,0) -> 92 | I7: =Calculations!Z4 -> High
A8: =Calculations!A5 -> Trident Limited | B8: =ROUND(Calculations!N5,1) -> 53 | C8: =ROUND(Calculations!Q5,1) -> 17.9 | D8: =ROUND(Calculations!R5,1) -> 100 | E8: =ROUND(Calculations!V5,1) -> 92 | F8: =ROUND(Calculations!W5,1) -> 59.5 | G8: =Calculations!X5 -> BB | H8: =ROUND(Calculations!Y5,0) -> 83 | I8: =Calculations!Z5 -> High
A9: =Calculations!A6 -> K.P.R. Mill Limited | B9: =ROUND(Calculations!N6,1) -> 56.6 | C9: =ROUND(Calculations!Q6,1) -> 83.6 | D9: =ROUND(Calculations!R6,1) -> 100 | E9: =ROUND(Calculations!V6,1) -> 30 | F9: =ROUND(Calculations!W6,1) -> 68 | G9: =Calculations!X6 -> BBB | H9: =ROUND(Calculations!Y6,0) -> 83 | I9: =Calculations!Z6 -> High
A10: =Calculations!A7 -> Page Industries | B10: =ROUND(Calculations!N7,1) -> 64.9 | C10: =ROUND(Calculations!Q7,1) -> 79.3 | D10: =ROUND(Calculations!R7,1) -> 100 | E10: =ROUND(Calculations!V7,1) -> 80 | F10: =ROUND(Calculations!W7,1) -> 77.8 | G10: =Calculations!X7 -> A | H10: =ROUND(Calculations!Y7,0) -> 83 | I10: =Calculations!Z7 -> High
A11: =Calculations!A8 -> Indo Count | B11: =ROUND(Calculations!N8,1) -> 54.9 | C11: =ROUND(Calculations!Q8,1) -> 57.5 | D11: =ROUND(Calculations!R8,1) -> 100 | E11: =ROUND(Calculations!V8,1) -> 70 | F11: =ROUND(Calculations!W8,1) -> 66.8 | G11: =Calculations!X8 -> BBB | H11: =ROUND(Calculations!Y8,0) -> 75 | I11: =Calculations!Z8 -> Medium
A12: =Calculations!A9 -> Pearl Global | B12: =ROUND(Calculations!N9,1) -> 56.4 | C12: =ROUND(Calculations!Q9,1) -> 53.8 | D12: =ROUND(Calculations!R9,1) -> 100 | E12: =ROUND(Calculations!V9,1) -> 30 | F12: =ROUND(Calculations!W9,1) -> 60.5 | G12: =Calculations!X9 -> BBB | H12: =ROUND(Calculations!Y9,0) -> 75 | I12: =Calculations!Z9 -> Medium
A13: =Calculations!A10 -> Welspun Living | B13: =ROUND(Calculations!N10,1) -> 69.7 | C13: =ROUND(Calculations!Q10,1) -> 63.7 | D13: =ROUND(Calculations!R10,1) -> 100 | E13: =ROUND(Calculations!V10,1) -> 83.5 | F13: =ROUND(Calculations!W10,1) -> 76.3 | G13: =Calculations!X10 -> A | H13: =ROUND(Calculations!Y10,0) -> 100 | I13: =Calculations!Z10 -> High
A14: =Calculations!A11 -> Siyaram's Silk Mills | B14: =ROUND(Calculations!N11,1) -> 53.5 | C14: =ROUND(Calculations!Q11,1) -> 18.6 | D14: =ROUND(Calculations!R11,1) -> 100 | E14: =ROUND(Calculations!V11,1) -> 30 | F14: =ROUND(Calculations!W11,1) -> 50.5 | G14: =Calculations!X11 -> BB | H14: =ROUND(Calculations!Y11,0) -> 83 | I14: =Calculations!Z11 -> High
A15: =Calculations!A12 -> Jindal Worldwide | B15: =ROUND(Calculations!N12,1) -> 46.9 | C15: =ROUND(Calculations!Q12,1) -> 1.4 | D15: =ROUND(Calculations!R12,1) -> 100 | E15: =ROUND(Calculations!V12,1) -> 15 | F15: =ROUND(Calculations!W12,1) -> 41.4 | G15: =Calculations!X12 -> B | H15: =ROUND(Calculations!Y12,0) -> 92 | I15: =Calculations!Z12 -> High
A16: =Calculations!A13 -> Grasim Industries | B16: =ROUND(Calculations!N13,1) -> 15.5 | C16: =ROUND(Calculations!Q13,1) -> 4.8 | D16: =ROUND(Calculations!R13,1) -> 100 | E16: =ROUND(Calculations!V13,1) -> 50 | F16: =ROUND(Calculations!W13,1) -> 34.9 | G16: =Calculations!X13 -> CCC | H16: =ROUND(Calculations!Y13,0) -> 92 | I16: =Calculations!Z13 -> High
... A19: =Calculations!A16 -> Vamani Overseas Pvt. Ltd. | B19: =ROUND(Calculations!N16,1) -> 50.9 | C19: =ROUND(Calculations!Q16,1) -> 48.7 | D19: =ROUND(Calculations!R16,1) -> 55 | E19: =ROUND(Calculations!V16,1) -> 40 | F19: =ROUND(Calculations!W16,1) -> 49.5 | G19: =Calculations!X16 -> B | H19: =ROUND(Calculations!Y16,0) -> 83 | I19: =Calculations!Z16 -> High
A21: Scores are calculated on the hidden Calculations sheet using peer min-max normalization and simple dimension averages. See Framework Overview for full methodology.

Sheet Calculations
A1: Company Name | B1: Emissions Intensity (raw, tCO2e/employee) | C1: Water Intensity (raw, KL/employee) | D1: Waste Intensity (raw, MT/employee) | E1: RE % (raw) | F1: Sustainable Materials % (raw) | G1: Emissions Intensity Score | H1: Renewable Energy % Score | I1: Water Intensity Score | J1: Waste Intensity Score | K1: Sustainable Materials % Score | L1: SBTi Status Score | M1: RE100 Membership Score | N1: ENVIRONMENTAL SCORE | O1: Gender Diversity Score | P1: Farmer Engagement Score | Q1: SOCIAL SCORE | R1: GOVERNANCE SCORE (Ownership Type) | S1: Reporting Framework Count | T1: Reporting Framework Score | U1: CDP Disclosure Score | V1: TRANSPARENCY SCORE | W1: OVERALL ESG SCORE | X1: ESG RATING | Y1: Data Coverage % | Z1: Confidence Level
A2: =LS_Main_Dataset!A2 -> Shahi Exports | B2: =IF(ISNUMBER(LS_Main_Dataset!AN2),LS_Main_Dataset!AN2,"") -> 4.21 | C2: =IFERROR(IF(ISNUMBER(LS_Main_Dataset!V2),LS_Main_Dataset!V2/LS_Main_Dataset!H2,""),"") -> 46.277094 | D2: =IFERROR(IF(ISNUMBER(LS_Main_Dataset!AF2),LS_Main_Dataset!AF2/LS_Main_Dataset!H2,""),"") -> 0.50425532 | E2: =IF(ISNUMBER(LS_Main_Dataset!S2),LS_Main_Dataset!S2,"") -> 65 | F2: =IF(ISNUMBER(LS_Main_Dataset!AD2),LS_Main_Dataset!AD2,"") -> 50 | G2: =IF(B2="","",(MAX($B$2:$B$16)-B2)/(MAX($B$2:$B$16)-MIN($B$2:$B$16))*100) -> 99.777195 | H2: =IF(E2="","",E2) -> 65 | I2: =IF(C2="","",(MAX($C$2:$C$16)-C2)/(MAX($C$2:$C$16)-MIN($C$2:$C$16))*100) -> 96.578202 | J2: =IF(D2="","",(MAX($D$2:$D$16)-D2)/(MAX($D$2:$D$16)-MIN($D$2:$D$16))*100) -> 99.357808 | K2: =IF(F2="","",F2) -> 50 | L2: =IF(LS_Main_Dataset!X2="Committed",100,IF(LS_Main_Dataset!X2="Not Committed",40,IF(LS_Main_Dataset!X2="Not a member",15,IF(LS_Main_Dataset!X2="Not found",10,IF(LS_Main_Dataset!X2="Not Disclosed",0,""))))) -> 15 | M2: =IF(LS_Main_Dataset!AC2="Yes",100,IF(LS_Main_Dataset!AC2="No",0,"")) -> 0 | N2: =AVERAGE(G2:M2) -> 60.816172 | O2: =LS_Main_Dataset!L2 -> 71.64 | P2: =IF(ISNUMBER(LS_Main_Dataset!AE2),100,IF(LS_Main_Dataset!AE2="Not Disclosed",0,"")) | Q2: =AVERAGE(O2:P2) -> 71.64 | R2: =IF(LS_Main_Dataset!G2="Public Listed",100,IF(LS_Main_Dataset!G2="Private",55,"")) -> 55 | S2: {=SUMPRODUCT(--ISNUMBER(SEARCH({"GRI","SASB","TCFD","BRSR","UNGC","Integrated Annual Report","Sustainability Report"},LS_Main_Dataset!N2)))} -> 1 | T2: =IF(S2=0,0,IF(S2=1,30,IF(S2=2,50,IF(S2=3,65,IF(S2=4,80,IF(S2=5,92,100)))))) -> 30 | U2: =IF(LS_Main_Dataset!Z2="A",100,IF(LS_Main_Dataset!Z2="A-",90,IF(LS_Main_Dataset!Z2="B",75,IF(LS_Main_Dataset!Z2="B-",65,IF(LS_Main_Dataset!Z2="C",50,IF(LS_Main_Dataset!Z2="D",25,IF(LS_Main_Dataset!Z2="Not Disclosed",0,""))))))) -> 75 | V2: =AVERAGE(T2:U2) -> 52.5 | W2: =N2*0.4+Q2*0.25+R2*0.2+V2*0.15 -> 61.111469 | X2: =IF(W2>=90,"AAA",IF(W2>=80,"AA",IF(W2>=70,"A",IF(W2>=60,"BBB",IF(W2>=50,"BB",IF(W2>=40,"B","CCC")))))) -> BBB | Y2: =COUNT(G2:M2,O2:P2,R2,T2:U2)/12*100 -> 91.666667 | Z2: =IF(Y2>=80,"High",IF(Y2>=60,"Medium","Low")) -> High
A3: =LS_Main_Dataset!A3 -> Vardhman Textiles | B3: =IF(ISNUMBER(LS_Main_Dataset!AN3),LS_Main_Dataset!AN3,"") -> 40.79 | C3: =IFERROR(IF(ISNUMBER(LS_Main_Dataset!V3),LS_Main_Dataset!V3/LS_Main_Dataset!H3,""),"") -> 203.72925 | D3: =IFERROR(IF(ISNUMBER(LS_Main_Dataset!AF3),LS_Main_Dataset!AF3/LS_Main_Dataset!H3,""),"") -> 0.76634247 | E3: =IF(ISNUMBER(LS_Main_Dataset!S3),LS_Main_Dataset!S3,"") -> 14.46 | F3: =IF(ISNUMBER(LS_Main_Dataset!AD3),LS_Main_Dataset!AD3,"") -> 28 | G3: =IF(B3="","",(MAX($B$2:$B$16)-B3)/(MAX($B$2:$B$16)-MIN($B$2:$B$16))*100) -> 97.513245 | H3: =IF(E3="","",E3) -> 14.46 | I3: =IF(C3="","",(MAX($C$2:$C$16)-C3)/(MAX($C$2:$C$16)-MIN($C$2:$C$16))*100) -> 82.80631 | J3: =IF(D3="","",(MAX($D$2:$D$16)-D3)/(MAX($D$2:$D$16)-MIN($D$2:$D$16))*100) -> 98.993579 | K3: =IF(F3="","",F3) -> 28 | L3: =IF(LS_Main_Dataset!X3="Committed",100,IF(LS_Main_Dataset!X3="Not Committed",40,IF(LS_Main_Dataset!X3="Not a member",15,IF(LS_Main_Dataset!X3="Not found",10,IF(LS_Main_Dataset!X3="Not Disclosed",0,""))))) -> 10 | M3: =IF(LS_Main_Dataset!AC3="Yes",100,IF(LS_Main_Dataset!AC3="No",0,"")) -> 0 | N3: =AVERAGE(G3:M3) -> 47.396162 | O3: =LS_Main_Dataset!L3 -> 34.38 | P3: =IF(ISNUMBER(LS_Main_Dataset!AE3),100,IF(LS_Main_Dataset!AE3="Not Disclosed",0,"")) | Q3: =AVERAGE(O3:P3) -> 34.38 | R3: =IF(LS_Main_Dataset!G3="Public Listed",100,IF(LS_Main_Dataset!G3="Private",55,"")) -> 100 | S3: {=SUMPRODUCT(--ISNUMBER(SEARCH({"GRI","SASB","TCFD","BRSR","UNGC","Integrated Annual Report","Sustainability Report"},LS_Main_Dataset!N3)))} -> 1 | T3: =IF(S3=0,0,IF(S3=1,30,IF(S3=2,50,IF(S3=3,65,IF(S3=4,80,IF(S3=5,92,100)))))) -> 30 | U3: =IF(LS_Main_Dataset!Z3="A",100,IF(LS_Main_Dataset!Z3="A-",90,IF(LS_Main_Dataset!Z3="B",75,IF(LS_Main_Dataset!Z3="B-",65,IF(LS_Main_Dataset!Z3="C",50,IF(LS_Main_Dataset!Z3="D",25,IF(LS_Main_Dataset!Z3="Not Disclosed",0,""))))))) | V3: =AVERAGE(T3:U3) -> 30 | W3: =N3*0.4+Q3*0.25+R3*0.2+V3*0.15 -> 52.053465 | X3: =IF(W3>=90,"AAA",IF(W3>=80,"AA",IF(W3>=70,"A",IF(W3>=60,"BBB",IF(W3>=50,"BB",IF(W3>=40,"B","CCC")))))) -> BB | Y3: =COUNT(G3:M3,O3:P3,R3,T3:U3)/12*100 -> 83.333333 | Z3: =IF(Y3>=80,"High",IF(Y3>=60,"Medium","Low")) -> High
A4: =LS_Main_Dataset!A4 -> Arvind Limited | B4: =IF(ISNUMBER(LS_Main_Dataset!AN4),LS_Main_Dataset!AN4,"") -> 13.33 | C4: =IFERROR(IF(ISNUMBER(LS_Main_Dataset!V4),LS_Main_Dataset!V4/LS_Main_Dataset!H4,""),"") -> 79.43304 | D4: =IFERROR(IF(ISNUMBER(LS_Main_Dataset!AF4),LS_Main_Dataset!AF4/LS_Main_Dataset!H4,""),"") -> 1.0354838 | E4: =IF(ISNUMBER(LS_Main_Dataset!S4),LS_Main_Dataset!S4,"") -> 37 | F4: =IF(ISNUMBER(LS_Main_Dataset!AD4),LS_Main_Dataset!AD4,"") -> 37 | G4: =IF(B4="","",(MAX($B$2:$B$16)-B4)/(MAX($B$2:$B$16)-MIN($B$2:$B$16))*100) -> 99.212754 | H4: =IF(E4="","",E4) -> 37 | I4: =IF(C4="","",(MAX($C$2:$C$16)-C4)/(MAX($C$2:$C$16)-MIN($C$2:$C$16))*100) -> 93.678145 | J4: =IF(D4="","",(MAX($D$2:$D$16)-D4)/(MAX($D$2:$D$16)-MIN($D$2:$D$16))*100) -> 98.619547 | K4: =IF(F4="","",F4) -> 37 | L4: =IF(LS_Main_Dataset!X4="Committed",100,IF(LS_Main_Dataset!X4="Not Committed",40,IF(LS_Main_Dataset!X4="Not a member",15,IF(LS_Main_Dataset!X4="Not found",10,IF(LS_Main_Dataset!X4="Not Disclosed",0,""))))) -> 100 | M4: =IF(LS_Main_Dataset!AC4="Yes",100,IF(LS_Main_Dataset!AC4="No",0,"")) -> 0 | N4: =AVERAGE(G4:M4) -> 66.501492 | O4: =LS_Main_Dataset!L4 -> 30.11 | P4: =IF(ISNUMBER(LS_Main_Dataset!AE4),100,IF(LS_Main_Dataset!AE4="Not Disclosed",0,"")) -> 100 | Q4: =AVERAGE(O4:P4) -> 65.055 | R4: =IF(LS_Main_Dataset!G4="Public Listed",100,IF(LS_Main_Dataset!G4="Private",55,"")) -> 100 | S4: {=SUMPRODUCT(--ISNUMBER(SEARCH({"GRI","SASB","TCFD","BRSR","UNGC","Integrated Annual Report","Sustainability Report"},LS_Main_Dataset!N4)))} -> 2 | T4: =IF(S4=0,0,IF(S4=1,30,IF(S4=2,50,IF(S4=3,65,IF(S4=4,80,IF(S4=5,92,100)))))) -> 50 | U4: =IF(LS_Main_Dataset!Z4="A",100,IF(LS_Main_Dataset!Z4="A-",90,IF(LS_Main_Dataset!Z4="B",75,IF(LS_Main_Dataset!Z4="B-",65,IF(LS_Main_Dataset!Z4="C",50,IF(LS_Main_Dataset!Z4="D",25,IF(LS_Main_Dataset!Z4="Not Disclosed",0,""))))))) | V4: =AVERAGE(T4:U4) -> 50 | W4: =N4*0.4+Q4*0.25+R4*0.2+V4*0.15 -> 70.364347 | X4: =IF(W4>=90,"AAA",IF(W4>=80,"AA",IF(W4>=70,"A",IF(W4>=60,"BBB",IF(W4>=50,"BB",IF(W4>=40,"B","CCC")))))) -> A | Y4: =COUNT(G4:M4,O4:P4,R4,T4:U4)/12*100 -> 91.666667 | Z4: =IF(Y4>=80,"High",IF(Y4>=60,"Medium","Low")) -> High
A5: =LS_Main_Dataset!A5 -> Trident Limited | B5: =IF(ISNUMBER(LS_Main_Dataset!AN5),LS_Main_Dataset!AN5,"") -> 65.15 | C5: =IFERROR(IF(ISNUMBER(LS_Main_Dataset!V5),LS_Main_Dataset!V5/LS_Main_Dataset!H5,""),"") -> 877.13485 | D5: =IFERROR(IF(ISNUMBER(LS_Main_Dataset!AF5),LS_Main_Dataset!AF5/LS_Main_Dataset!H5,""),"") -> 16.080591 | E5: =IF(ISNUMBER(LS_Main_Dataset!S5),LS_Main_Dataset!S5,"") -> 34.9 | F5: =IF(ISNUMBER(LS_Main_Dataset!AD5),LS_Main_Dataset!AD5,"") -> 38.5 | G5: =IF(B5="","",(MAX($B$2:$B$16)-B5)/(MAX($B$2:$B$16)-MIN($B$2:$B$16))*100) -> 96.005595 | H5: =IF(E5="","",E5) -> 34.9 | I5: =IF(C5="","",(MAX($C$2:$C$16)-C5)/(MAX($C$2:$C$16)-MIN($C$2:$C$16))*100) -> 23.90544 | J5: =IF(D5="","",(MAX($D$2:$D$16)-D5)/(MAX($D$2:$D$16)-MIN($D$2:$D$16))*100) -> 77.711009 | K5: =IF(F5="","",F5) -> 38.5 | L5: =IF(LS_Main_Dataset!X5="Committed",100,IF(LS_Main_Dataset!X5="Not Committed",40,IF(LS_Main_Dataset!X5="Not a member",15,IF(LS_Main_Dataset!X5="Not found",10,IF(LS_Main_Dataset!X5="Not Disclosed",0,""))))) -> 100 | M5: =IF(LS_Main_Dataset!AC5="Yes",100,IF(LS_Main_Dataset!AC5="No",0,"")) -> 0 | N5: =AVERAGE(G5:M5) -> 53.003149 | O5: =LS_Main_Dataset!L5 -> 17.88 | P5: =IF(ISNUMBER(LS_Main_Dataset!AE5),100,IF(LS_Main_Dataset!AE5="Not Disclosed",0,"")) | Q5: =AVERAGE(O5:P5) -> 17.88 | R5: =IF(LS_Main_Dataset!G5="Public Listed",100,IF(LS_Main_Dataset!G5="Private",55,"")) -> 100 | S5: {=SUMPRODUCT(--ISNUMBER(SEARCH({"GRI","SASB","TCFD","BRSR","UNGC","Integrated Annual Report","Sustainability Report"},LS_Main_Dataset!N5)))} -> 5 | T5: =IF(S5=0,0,IF(S5=1,30,IF(S5=2,50,IF(S5=3,65,IF(S5=4,80,IF(S5=5,92,100)))))) -> 92 | U5: =IF(LS_Main_Dataset!Z5="A",100,IF(LS_Main_Dataset!Z5="A-",90,IF(LS_Main_Dataset!Z5="B",75,IF(LS_Main_Dataset!Z5="B-",65,IF(LS_Main_Dataset!Z5="C",50,IF(LS_Main_Dataset!Z5="D",25,IF(LS_Main_Dataset!Z5="Not Disclosed",0,""))))))) | V5: =AVERAGE(T5:U5) -> 92 | W5: =N5*0.4+Q5*0.25+R5*0.2+V5*0.15 -> 59.47126 | X5: =IF(W5>=90,"AAA",IF(W5>=80,"AA",IF(W5>=70,"A",IF(W5>=60,"BBB",IF(W5>=50,"BB",IF(W5>=40,"B","CCC")))))) -> BB | Y5: =COUNT(G5:M5,O5:P5,R5,T5:U5)/12*100 -> 83.333333 | Z5: =IF(Y5>=80,"High",IF(Y5>=60,"Medium","Low")) -> High
A6: =LS_Main_Dataset!A6 -> K.P.R. Mill Limited | B6: =IF(ISNUMBER(LS_Main_Dataset!AN6),LS_Main_Dataset!AN6,"") -> 10.66 | C6: =IFERROR(IF(ISNUMBER(LS_Main_Dataset!V6),LS_Main_Dataset!V6/LS_Main_Dataset!H6,""),"") -> 88.6804 | D6: =IFERROR(IF(ISNUMBER(LS_Main_Dataset!AF6),LS_Main_Dataset!AF6/LS_Main_Dataset!H6,""),"") -> 0.088013863 | E6: =IF(ISNUMBER(LS_Main_Dataset!S6),LS_Main_Dataset!S6,"") -> 24.1 | F6: =IF(ISNUMBER(LS_Main_Dataset!AD6),LS_Main_Dataset!AD6,"") -> 40 | G6: =IF(B6="","",(MAX($B$2:$B$16)-B6)/(MAX($B$2:$B$16)-MIN($B$2:$B$16))*100) -> 99.378002 | H6: =IF(E6="","",E6) -> 24.1 | I6: =IF(C6="","",(MAX($C$2:$C$16)-C6)/(MAX($C$2:$C$16)-MIN($C$2:$C$16))*100) -> 92.869305 | J6: =IF(D6="","",(MAX($D$2:$D$16)-D6)/(MAX($D$2:$D$16)-MIN($D$2:$D$16))*100) -> 99.936268 | K6: =IF(F6="","",F6) -> 40 | L6: =IF(LS_Main_Dataset!X6="Committed",100,IF(LS_Main_Dataset!X6="Not Committed",40,IF(LS_Main_Dataset!X6="Not a member",15,IF(LS_Main_Dataset!X6="Not found",10,IF(LS_Main_Dataset!X6="Not Disclosed",0,""))))) -> 40 | M6: =IF(LS_Main_Dataset!AC6="Yes",100,IF(LS_Main_Dataset!AC6="No",0,"")) -> 0 | N6: =AVERAGE(G6:M6) -> 56.611939 | O6: =LS_Main_Dataset!L6 -> 83.62 | P6: =IF(ISNUMBER(LS_Main_Dataset!AE6),100,IF(LS_Main_Dataset!AE6="Not Disclosed",0,"")) | Q6: =AVERAGE(O6:P6) -> 83.62 | R6: =IF(LS_Main_Dataset!G6="Public Listed",100,IF(LS_Main_Dataset!G6="Private",55,"")) -> 100 | S6: {=SUMPRODUCT(--ISNUMBER(SEARCH({"GRI","SASB","TCFD","BRSR","UNGC","Integrated Annual Report","Sustainability Report"},LS_Main_Dataset!N6)))} -> 1 | T6: =IF(S6=0,0,IF(S6=1,30,IF(S6=2,50,IF(S6=3,65,IF(S6=4,80,IF(S6=5,92,100)))))) -> 30 | U6: =IF(LS_Main_Dataset!Z6="A",100,IF(LS_Main_Dataset!Z6="A-",90,IF(LS_Main_Dataset!Z6="B",75,IF(LS_Main_Dataset!Z6="B-",65,IF(LS_Main_Dataset!Z6="C",50,IF(LS_Main_Dataset!Z6="D",25,IF(LS_Main_Dataset!Z6="Not Disclosed",0,""))))))) | V6: =AVERAGE(T6:U6) -> 30 | W6: =N6*0.4+Q6*0.25+R6*0.2+V6*0.15 -> 68.049776 | X6: =IF(W6>=90,"AAA",IF(W6>=80,"AA",IF(W6>=70,"A",IF(W6>=60,"BBB",IF(W6>=50,"BB",IF(W6>=40,"B","CCC")))))) -> BBB | Y6: =COUNT(G6:M6,O6:P6,R6,T6:U6)/12*100 -> 83.333333 | Z6: =IF(Y6>=80,"High",IF(Y6>=60,"Medium","Low")) -> High
A7: =LS_Main_Dataset!A7 -> Page Industries | B7: =IF(ISNUMBER(LS_Main_Dataset!AN7),LS_Main_Dataset!AN7,"") -> 0.63 | C7: =IFERROR(IF(ISNUMBER(LS_Main_Dataset!V7),LS_Main_Dataset!V7/LS_Main_Dataset!H7,""),"") -> 8.5017911 | D7: =IFERROR(IF(ISNUMBER(LS_Main_Dataset!AF7),LS_Main_Dataset!AF7/LS_Main_Dataset!H7,""),"") -> 0.30036015 | E7: =IF(ISNUMBER(LS_Main_Dataset!S7),LS_Main_Dataset!S7,"") -> 33 | F7: =IF(ISNUMBER(LS_Main_Dataset!AD7),LS_Main_Dataset!AD7,"") -> 82 | G7: =IF(B7="","",(MAX($B$2:$B$16)-B7)/(MAX($B$2:$B$16)-MIN($B$2:$B$16))*100) -> 99.998762 | H7: =IF(E7="","",E7) -> 33 | I7: =IF(C7="","",(MAX($C$2:$C$16)-C7)/(MAX($C$2:$C$16)-MIN($C$2:$C$16))*100) -> 99.8823 | J7: =IF(D7="","",(MAX($D$2:$D$16)-D7)/(MAX($D$2:$D$16)-MIN($D$2:$D$16))*100) -> 99.641166 | K7: =IF(F7="","",F7) -> 82 | L7: =IF(LS_Main_Dataset!X7="Committed",100,IF(LS_Main_Dataset!X7="Not Committed",40,IF(LS_Main_Dataset!X7="Not a member",15,IF(LS_Main_Dataset!X7="Not found",10,IF(LS_Main_Dataset!X7="Not Disclosed",0,""))))) -> 40 | M7: =IF(LS_Main_Dataset!AC7="Yes",100,IF(LS_Main_Dataset!AC7="No",0,"")) -> 0 | N7: =AVERAGE(G7:M7) -> 64.931747 | O7: =LS_Main_Dataset!L7 -> 79.33 | P7: =IF(ISNUMBER(LS_Main_Dataset!AE7),100,IF(LS_Main_Dataset!AE7="Not Disclosed",0,"")) | Q7: =AVERAGE(O7:P7) -> 79.33 | R7: =IF(LS_Main_Dataset!G7="Public Listed",100,IF(LS_Main_Dataset!G7="Private",55,"")) -> 100 | S7: {=SUMPRODUCT(--ISNUMBER(SEARCH({"GRI","SASB","TCFD","BRSR","UNGC","Integrated Annual Report","Sustainability Report"},LS_Main_Dataset!N7)))} -> 4 | T7: =IF(S7=0,0,IF(S7=1,30,IF(S7=2,50,IF(S7=3,65,IF(S7=4,80,IF(S7=5,92,100)))))) -> 80 | U7: =IF(LS_Main_Dataset!Z7="A",100,IF(LS_Main_Dataset!Z7="A-",90,IF(LS_Main_Dataset!Z7="B",75,IF(LS_Main_Dataset!Z7="B-",65,IF(LS_Main_Dataset!Z7="C",50,IF(LS_Main_Dataset!Z7="D",25,IF(LS_Main_Dataset!Z7="Not Disclosed",0,""))))))) | V7: =AVERAGE(T7:U7) -> 80 | W7: =N7*0.4+Q7*0.25+R7*0.2+V7*0.15 -> 77.805199 | X7: =IF(W7>=90,"AAA",IF(W7>=80,"AA",IF(W7>=70,"A",IF(W7>=60,"BBB",IF(W7>=50,"BB",IF(W7>=40,"B","CCC")))))) -> A | Y7: =COUNT(G7:M7,O7:P7,R7,T7:U7)/12*100 -> 83.333333 | Z7: =IF(Y7>=80,"High",IF(Y7>=60,"Medium","Low")) -> High
A8: =LS_Main_Dataset!A8 -> Indo Count | B8: =IF(ISNUMBER(LS_Main_Dataset!AN8),LS_Main_Dataset!AN8,"") -> 39.02 | C8: =IFERROR(IF(ISNUMBER(LS_Main_Dataset!V8),LS_Main_Dataset!V8/LS_Main_Dataset!H8,""),"") | D8: =IFERROR(IF(ISNUMBER(LS_Main_Dataset!AF8),LS_Main_Dataset!AF8/LS_Main_Dataset!H8,""),"") | E8: =IF(ISNUMBER(LS_Main_Dataset!S8),LS_Main_Dataset!S8,"") | F8: =IF(ISNUMBER(LS_Main_Dataset!AD8),LS_Main_Dataset!AD8,"") -> 22 | G8: =IF(B8="","",(MAX($B$2:$B$16)-B8)/(MAX($B$2:$B$16)-MIN($B$2:$B$16))*100) -> 97.622791 | H8: =IF(E8="","",E8) | I8: =IF(C8="","",(MAX($C$2:$C$16)-C8)/(MAX($C$2:$C$16)-MIN($C$2:$C$16))*100) | J8: =IF(D8="","",(MAX($D$2:$D$16)-D8)/(MAX($D$2:$D$16)-MIN($D$2:$D$16))*100) | K8: =IF(F8="","",F8) -> 22 | L8: =IF(LS_Main_Dataset!X8="Committed",100,IF(LS_Main_Dataset!X8="Not Committed",40,IF(LS_Main_Dataset!X8="Not a member",15,IF(LS_Main_Dataset!X8="Not found",10,IF(LS_Main_Dataset!X8="Not Disclosed",0,""))))) -> 100 | M8: =IF(LS_Main_Dataset!AC8="Yes",100,IF(LS_Main_Dataset!AC8="No",0,"")) -> 0 | N8: =AVERAGE(G8:M8) -> 54.905698 | O8: =LS_Main_Dataset!L8 -> 15.02 | P8: =IF(ISNUMBER(LS_Main_Dataset!AE8),100,IF(LS_Main_Dataset!AE8="Not Disclosed",0,"")) -> 100 | Q8: =AVERAGE(O8:P8) -> 57.51 | R8: =IF(LS_Main_Dataset!G8="Public Listed",100,IF(LS_Main_Dataset!G8="Private",55,"")) -> 100 | S8: {=SUMPRODUCT(--ISNUMBER(SEARCH({"GRI","SASB","TCFD","BRSR","UNGC","Integrated Annual Report","Sustainability Report"},LS_Main_Dataset!N8)))} -> 3 | T8: =IF(S8=0,0,IF(S8=1,30,IF(S8=2,50,IF(S8=3,65,IF(S8=4,80,IF(S8=5,92,100)))))) -> 65 | U8: =IF(LS_Main_Dataset!Z8="A",100,IF(LS_Main_Dataset!Z8="A-",90,IF(LS_Main_Dataset!Z8="B",75,IF(LS_Main_Dataset!Z8="B-",65,IF(LS_Main_Dataset!Z8="C",50,IF(LS_Main_Dataset!Z8="D",25,IF(LS_Main_Dataset!Z8="Not Disclosed",0,""))))))) -> 75 | V8: =AVERAGE(T8:U8) -> 70 | W8: =N8*0.4+Q8*0.25+R8*0.2+V8*0.15 -> 66.839779 | X8: =IF(W8>=90,"AAA",IF(W8>=80,"AA",IF(W8>=70,"A",IF(W8>=60,"BBB",IF(W8>=50,"BB",IF(W8>=40,"B","CCC")))))) -> BBB | Y8: =COUNT(G8:M8,O8:P8,R8,T8:U8)/12*100 -> 75 | Z8: =IF(Y8>=80,"High",IF(Y8>=60,"Medium","Low")) -> Medium
A9: =LS_Main_Dataset!A9 -> Pearl Global | B9: =IF(ISNUMBER(LS_Main_Dataset!AN9),LS_Main_Dataset!AN9,"") -> 0.66 | C9: =IFERROR(IF(ISNUMBER(LS_Main_Dataset!V9),LS_Main_Dataset!V9/LS_Main_Dataset!H9,""),"") -> 12.162925 | D9: =IFERROR(IF(ISNUMBER(LS_Main_Dataset!AF9),LS_Main_Dataset!AF9/LS_Main_Dataset!H9,""),"") -> 0.16086227 | E9: =IF(ISNUMBER(LS_Main_Dataset!S9),LS_Main_Dataset!S9,"") | F9: =IF(ISNUMBER(LS_Main_Dataset!AD9),LS_Main_Dataset!AD9,"") -> 24 | G9: =IF(B9="","",(MAX($B$2:$B$16)-B9)/(MAX($B$2:$B$16)-MIN($B$2:$B$16))*100) -> 99.996905 | H9: =IF(E9="","",E9) | I9: =IF(C9="","",(MAX($C$2:$C$16)-C9)/(MAX($C$2:$C$16)-MIN($C$2:$C$16))*100) -> 99.562071 | J9: =IF(D9="","",(MAX($D$2:$D$16)-D9)/(MAX($D$2:$D$16)-MIN($D$2:$D$16))*100) -> 99.835029 | K9: =IF(F9="","",F9) -> 24 | L9: =IF(LS_Main_Dataset!X9="Committed",100,IF(LS_Main_Dataset!X9="Not Committed",40,IF(LS_Main_Dataset!X9="Not a member",15,IF(LS_Main_Dataset!X9="Not found",10,IF(LS_Main_Dataset!X9="Not Disclosed",0,""))))) -> 15 | M9: =IF(LS_Main_Dataset!AC9="Yes",100,IF(LS_Main_Dataset!AC9="No",0,"")) -> 0 | N9: =AVERAGE(G9:M9) -> 56.399001 | O9: =LS_Main_Dataset!L9 -> 53.83 | P9: =IF(ISNUMBER(LS_Main_Dataset!AE9),100,IF(LS_Main_Dataset!AE9="Not Disclosed",0,"")) | Q9: =AVERAGE(O9:P9) -> 53.83 | R9: =IF(LS_Main_Dataset!G9="Public Listed",100,IF(LS_Main_Dataset!G9="Private",55,"")) -> 100 | S9: {=SUMPRODUCT(--ISNUMBER(SEARCH({"GRI","SASB","TCFD","BRSR","UNGC","Integrated Annual Report","Sustainability Report"},LS_Main_Dataset!N9)))} -> 1 | T9: =IF(S9=0,0,IF(S9=1,30,IF(S9=2,50,IF(S9=3,65,IF(S9=4,80,IF(S9=5,92,100)))))) -> 30 | U9: =IF(LS_Main_Dataset!Z9="A",100,IF(LS_Main_Dataset!Z9="A-",90,IF(LS_Main_Dataset!Z9="B",75,IF(LS_Main_Dataset!Z9="B-",65,IF(LS_Main_Dataset!Z9="C",50,IF(LS_Main_Dataset!Z9="D",25,IF(LS_Main_Dataset!Z9="Not Disclosed",0,""))))))) | V9: =AVERAGE(T9:U9) -> 30 | W9: =N9*0.4+Q9*0.25+R9*0.2+V9*0.15 -> 60.5171 | X9: =IF(W9>=90,"AAA",IF(W9>=80,"AA",IF(W9>=70,"A",IF(W9>=60,"BBB",IF(W9>=50,"BB",IF(W9>=40,"B","CCC")))))) -> BBB | Y9: =COUNT(G9:M9,O9:P9,R9,T9:U9)/12*100 -> 75 | Z9: =IF(Y9>=80,"High",IF(Y9>=60,"Medium","Low")) -> Medium
A10: =LS_Main_Dataset!A10 -> Welspun Living | B10: =IF(ISNUMBER(LS_Main_Dataset!AN10),LS_Main_Dataset!AN10,"") -> 26.05 | C10: =IFERROR(IF(ISNUMBER(LS_Main_Dataset!V10),LS_Main_Dataset!V10/LS_Main_Dataset!H10,""),"") -> 181.71543 | D10: =IFERROR(IF(ISNUMBER(LS_Main_Dataset!AF10),LS_Main_Dataset!AF10/LS_Main_Dataset!H10,""),"") -> 1.1370179 | E10: =IF(ISNUMBER(LS_Main_Dataset!S10),LS_Main_Dataset!S10,"") -> 30.54 | F10: =IF(ISNUMBER(LS_Main_Dataset!AD10),LS_Main_Dataset!AD10,"") -> 76 | G10: =IF(B10="","",(MAX($B$2:$B$16)-B10)/(MAX($B$2:$B$16)-MIN($B$2:$B$16))*100) -> 98.425509 | H10: =IF(E10="","",E10) -> 30.54 | I10: =IF(C10="","",(MAX($C$2:$C$16)-C10)/(MAX($C$2:$C$16)-MIN($C$2:$C$16))*100) -> 84.731796 | J10: =IF(D10="","",(MAX($D$2:$D$16)-D10)/(MAX($D$2:$D$16)-MIN($D$2:$D$16))*100) -> 98.478443 | K10: =IF(F10="","",F10) -> 76 | L10: =IF(LS_Main_Dataset!X10="Committed",100,IF(LS_Main_Dataset!X10="Not Committed",40,IF(LS_Main_Dataset!X10="Not a member",15,IF(LS_Main_Dataset!X10="Not found",10,IF(LS_Main_Dataset!X10="Not Disclosed",0,""))))) -> 100 | M10: =IF(LS_Main_Dataset!AC10="Yes",100,IF(LS_Main_Dataset!AC10="No",0,"")) -> 0 | N10: =AVERAGE(G10:M10) -> 69.739392 | O10: =LS_Main_Dataset!L10 -> 27.39 | P10: =IF(ISNUMBER(LS_Main_Dataset!AE10),100,IF(LS_Main_Dataset!AE10="Not Disclosed",0,"")) -> 100 | Q10: =AVERAGE(O10:P10) -> 63.695 | R10: =IF(LS_Main_Dataset!G10="Public Listed",100,IF(LS_Main_Dataset!G10="Private",55,"")) -> 100 | S10: {=SUMPRODUCT(--ISNUMBER(SEARCH({"GRI","SASB","TCFD","BRSR","UNGC","Integrated Annual Report","Sustainability Report"},LS_Main_Dataset!N10)))} -> 5 | T10: =IF(S10=0,0,IF(S10=1,30,IF(S10=2,50,IF(S10=3,65,IF(S10=4,80,IF(S10=5,92,100)))))) -> 92 | U10: =IF(LS_Main_Dataset!Z10="A",100,IF(LS_Main_Dataset!Z10="A-",90,IF(LS_Main_Dataset!Z10="B",75,IF(LS_Main_Dataset!Z10="B-",65,IF(LS_Main_Dataset!Z10="C",50,IF(LS_Main_Dataset!Z10="D",25,IF(LS_Main_Dataset!Z10="Not Disclosed",0,""))))))) -> 75 | V10: =AVERAGE(T10:U10) -> 83.5 | W10: =N10*0.4+Q10*0.25+R10*0.2+V10*0.15 -> 76.344507 | X10: =IF(W10>=90,"AAA",IF(W10>=80,"AA",IF(W10>=70,"A",IF(W10>=60,"BBB",IF(W10>=50,"BB",IF(W10>=40,"B","CCC")))))) -> A | Y10: =COUNT(G10:M10,O10:P10,R10,T10:U10)/12*100 -> 100 | Z10: =IF(Y10>=80,"High",IF(Y10>=60,"Medium","Low")) -> High
A11: =LS_Main_Dataset!A11 -> Siyaram's Silk Mills | B11: =IF(ISNUMBER(LS_Main_Dataset!AN11),LS_Main_Dataset!AN11,"") -> 21.89 | C11: =IFERROR(IF(ISNUMBER(LS_Main_Dataset!V11),LS_Main_Dataset!V11/LS_Main_Dataset!H11,""),"") -> 72.603461 | D11: =IFERROR(IF(ISNUMBER(LS_Main_Dataset!AF11),LS_Main_Dataset!AF11/LS_Main_Dataset!H11,""),"") -> 1.3423324 | E11: =IF(ISNUMBER(LS_Main_Dataset!S11),LS_Main_Dataset!S11,"") -> 1.66 | F11: =IF(ISNUMBER(LS_Main_Dataset!AD11),LS_Main_Dataset!AD11,"") -> 41.45 | G11: =IF(B11="","",(MAX($B$2:$B$16)-B11)/(MAX($B$2:$B$16)-MIN($B$2:$B$16))*100) -> 98.682973 | H11: =IF(E11="","",E11) -> 1.66 | I11: =IF(C11="","",(MAX($C$2:$C$16)-C11)/(MAX($C$2:$C$16)-MIN($C$2:$C$16))*100) -> 94.275509 | J11: =IF(D11="","",(MAX($D$2:$D$16)-D11)/(MAX($D$2:$D$16)-MIN($D$2:$D$16))*100) -> 98.193112 | K11: =IF(F11="","",F11) -> 41.45 | L11: =IF(LS_Main_Dataset!X11="Committed",100,IF(LS_Main_Dataset!X11="Not Committed",40,IF(LS_Main_Dataset!X11="Not a member",15,IF(LS_Main_Dataset!X11="Not found",10,IF(LS_Main_Dataset!X11="Not Disclosed",0,""))))) -> 40 | M11: =IF(LS_Main_Dataset!AC11="Yes",100,IF(LS_Main_Dataset!AC11="No",0,"")) -> 0 | N11: =AVERAGE(G11:M11) -> 53.465942 | O11: =LS_Main_Dataset!L11 -> 18.62 | P11: =IF(ISNUMBER(LS_Main_Dataset!AE11),100,IF(LS_Main_Dataset!AE11="Not Disclosed",0,"")) | Q11: =AVERAGE(O11:P11) -> 18.62 | R11: =IF(LS_Main_Dataset!G11="Public Listed",100,IF(LS_Main_Dataset!G11="Private",55,"")) -> 100 | S11: {=SUMPRODUCT(--ISNUMBER(SEARCH({"GRI","SASB","TCFD","BRSR","UNGC","Integrated Annual Report","Sustainability Report"},LS_Main_Dataset!N11)))} -> 1 | T11: =IF(S11=0,0,IF(S11=1,30,IF(S11=2,50,IF(S11=3,65,IF(S11=4,80,IF(S11=5,92,100)))))) -> 30 | U11: =IF(LS_Main_Dataset!Z11="A",100,IF(LS_Main_Dataset!Z11="A-",90,IF(LS_Main_Dataset!Z11="B",75,IF(LS_Main_Dataset!Z11="B-",65,IF(LS_Main_Dataset!Z11="C",50,IF(LS_Main_Dataset!Z11="D",25,IF(LS_Main_Dataset!Z11="Not Disclosed",0,""))))))) | V11: =AVERAGE(T11:U11) -> 30 | W11: =N11*0.4+Q11*0.25+R11*0.2+V11*0.15 -> 50.541377 | X11: =IF(W11>=90,"AAA",IF(W11>=80,"AA",IF(W11>=70,"A",IF(W11>=60,"BBB",IF(W11>=50,"BB",IF(W11>=40,"B","CCC")))))) -> BB | Y11: =COUNT(G11:M11,O11:P11,R11,T11:U11)/12*100 -> 83.333333 | Z11: =IF(Y11>=80,"High",IF(Y11>=60,"Medium","Low")) -> High
A12: =LS_Main_Dataset!A12 -> Jindal Worldwide | B12: =IF(ISNUMBER(LS_Main_Dataset!AN12),LS_Main_Dataset!AN12,"") -> 104.95 | C12: =IFERROR(IF(ISNUMBER(LS_Main_Dataset!V12),LS_Main_Dataset!V12/LS_Main_Dataset!H12,""),"") -> 70.21034 | D12: =IFERROR(IF(ISNUMBER(LS_Main_Dataset!AF12),LS_Main_Dataset!AF12/LS_Main_Dataset!H12,""),"") -> 0.14717422 | E12: =IF(ISNUMBER(LS_Main_Dataset!S12),LS_Main_Dataset!S12,"") -> 0.71 | F12: =IF(ISNUMBER(LS_Main_Dataset!AD12),LS_Main_Dataset!AD12,"") -> 0 | G12: =IF(B12="","",(MAX($B$2:$B$16)-B12)/(MAX($B$2:$B$16)-MIN($B$2:$B$16))*100) -> 93.542358 | H12: =IF(E12="","",E12) -> 0.71 | I12: =IF(C12="","",(MAX($C$2:$C$16)-C12)/(MAX($C$2:$C$16)-MIN($C$2:$C$16))*100) -> 94.484829 | J12: =IF(D12="","",(MAX($D$2:$D$16)-D12)/(MAX($D$2:$D$16)-MIN($D$2:$D$16))*100) -> 99.854052 | K12: =IF(F12="","",F12) -> 0 | L12: =IF(LS_Main_Dataset!X12="Committed",100,IF(LS_Main_Dataset!X12="Not Committed",40,IF(LS_Main_Dataset!X12="Not a member",15,IF(LS_Main_Dataset!X12="Not found",10,IF(LS_Main_Dataset!X12="Not Disclosed",0,""))))) -> 40 | M12: =IF(LS_Main_Dataset!AC12="Yes",100,IF(LS_Main_Dataset!AC12="No",0,"")) -> 0 | N12: =AVERAGE(G12:M12) -> 46.941605 | O12: =LS_Main_Dataset!L12 -> 1.35 | P12: =IF(ISNUMBER(LS_Main_Dataset!AE12),100,IF(LS_Main_Dataset!AE12="Not Disclosed",0,"")) | Q12: =AVERAGE(O12:P12) -> 1.35 | R12: =IF(LS_Main_Dataset!G12="Public Listed",100,IF(LS_Main_Dataset!G12="Private",55,"")) -> 100 | S12: {=SUMPRODUCT(--ISNUMBER(SEARCH({"GRI","SASB","TCFD","BRSR","UNGC","Integrated Annual Report","Sustainability Report"},LS_Main_Dataset!N12)))} -> 1 | T12: =IF(S12=0,0,IF(S12=1,30,IF(S12=2,50,IF(S12=3,65,IF(S12=4,80,IF(S12=5,92,100)))))) -> 30 | U12: =IF(LS_Main_Dataset!Z12="A",100,IF(LS_Main_Dataset!Z12="A-",90,IF(LS_Main_Dataset!Z12="B",75,IF(LS_Main_Dataset!Z12="B-",65,IF(LS_Main_Dataset!Z12="C",50,IF(LS_Main_Dataset!Z12="D",25,IF(LS_Main_Dataset!Z12="Not Disclosed",0,""))))))) -> 0 | V12: =AVERAGE(T12:U12) -> 15 | W12: =N12*0.4+Q12*0.25+R12*0.2+V12*0.15 -> 41.364142 | X12: =IF(W12>=90,"AAA",IF(W12>=80,"AA",IF(W12>=70,"A",IF(W12>=60,"BBB",IF(W12>=50,"BB",IF(W12>=40,"B","CCC")))))) -> B | Y12: =COUNT(G12:M12,O12:P12,R12,T12:U12)/12*100 -> 91.666667 | Z12: =IF(Y12>=80,"High",IF(Y12>=60,"Medium","Low")) -> High
A13: =LS_Main_Dataset!A13 -> Grasim Industries | B13: =IF(ISNUMBER(LS_Main_Dataset!AN13),LS_Main_Dataset!AN13,"") -> 1616.37 | C13: =IFERROR(IF(ISNUMBER(LS_Main_Dataset!V13),LS_Main_Dataset!V13/LS_Main_Dataset!H13,""),"") -> 1150.4425 | D13: =IFERROR(IF(ISNUMBER(LS_Main_Dataset!AF13),LS_Main_Dataset!AF13/LS_Main_Dataset!H13,""),"") -> 71.998914 | E13: =IF(ISNUMBER(LS_Main_Dataset!S13),LS_Main_Dataset!S13,"") -> 6.5 | F13: =IF(ISNUMBER(LS_Main_Dataset!AD13),LS_Main_Dataset!AD13,"") -> 62 | G13: =IF(B13="","",(MAX($B$2:$B$16)-B13)/(MAX($B$2:$B$16)-MIN($B$2:$B$16))*100) -> 0 | H13: =IF(E13="","",E13) -> 6.5 | I13: =IF(C13="","",(MAX($C$2:$C$16)-C13)/(MAX($C$2:$C$16)-MIN($C$2:$C$16))*100) -> 0 | J13: =IF(D13="","",(MAX($D$2:$D$16)-D13)/(MAX($D$2:$D$16)-MIN($D$2:$D$16))*100) -> 0 | K13: =IF(F13="","",F13) -> 62 | L13: =IF(LS_Main_Dataset!X13="Committed",100,IF(LS_Main_Dataset!X13="Not Committed",40,IF(LS_Main_Dataset!X13="Not a member",15,IF(LS_Main_Dataset!X13="Not found",10,IF(LS_Main_Dataset!X13="Not Disclosed",0,""))))) -> 40 | M13: =IF(LS_Main_Dataset!AC13="Yes",100,IF(LS_Main_Dataset!AC13="No",0,"")) -> 0 | N13: =AVERAGE(G13:M13) -> 15.5 | O13: =LS_Main_Dataset!L13 -> 4.8 | P13: =IF(ISNUMBER(LS_Main_Dataset!AE13),100,IF(LS_Main_Dataset!AE13="Not Disclosed",0,"")) | Q13: =AVERAGE(O13:P13) -> 4.8 | R13: =IF(LS_Main_Dataset!G13="Public Listed",100,IF(LS_Main_Dataset!G13="Private",55,"")) -> 100 | S13: {=SUMPRODUCT(--ISNUMBER(SEARCH({"GRI","SASB","TCFD","BRSR","UNGC","Integrated Annual Report","Sustainability Report"},LS_Main_Dataset!N13)))} -> 6 | T13: =IF(S13=0,0,IF(S13=1,30,IF(S13=2,50,IF(S13=3,65,IF(S13=4,80,IF(S13=5,92,100)))))) -> 100 | U13: =IF(LS_Main_Dataset!Z13="A",100,IF(LS_Main_Dataset!Z13="A-",90,IF(LS_Main_Dataset!Z13="B",75,IF(LS_Main_Dataset!Z13="B-",65,IF(LS_Main_Dataset!Z13="C",50,IF(LS_Main_Dataset!Z13="D",25,IF(LS_Main_Dataset!Z13="Not Disclosed",0,""))))))) -> 0 | V13: =AVERAGE(T13:U13) -> 50 | W13: =N13*0.4+Q13*0.25+R13*0.2+V13*0.15 -> 34.9 | X13: =IF(W13>=90,"AAA",IF(W13>=80,"AA",IF(W13>=70,"A",IF(W13>=60,"BBB",IF(W13>=50,"BB",IF(W13>=40,"B","CCC")))))) -> CCC | Y13: =COUNT(G13:M13,O13:P13,R13,T13:U13)/12*100 -> 91.666667 | Z13: =IF(Y13>=80,"High",IF(Y13>=60,"Medium","Low")) -> High
... A16: =LS_Main_Dataset!A16 -> Vamani Overseas Pvt. Ltd. | B16: =IF(ISNUMBER(LS_Main_Dataset!AN16),LS_Main_Dataset!AN16,"") -> 0.61 | C16: =IFERROR(IF(ISNUMBER(LS_Main_Dataset!V16),LS_Main_Dataset!V16/LS_Main_Dataset!H16,""),"") -> 7.156141 | D16: =IFERROR(IF(ISNUMBER(LS_Main_Dataset!AF16),LS_Main_Dataset!AF16/LS_Main_Dataset!H16,""),"") -> 0.042154571 | E16: =IF(ISNUMBER(LS_Main_Dataset!S16),LS_Main_Dataset!S16,"") -> 5.1 | F16: =IF(ISNUMBER(LS_Main_Dataset!AD16),LS_Main_Dataset!AD16,"") | G16: =IF(B16="","",(MAX($B$2:$B$16)-B16)/(MAX($B$2:$B$16)-MIN($B$2:$B$16))*100) -> 100 | H16: =IF(E16="","",E16) -> 5.1 | I16: =IF(C16="","",(MAX($C$2:$C$16)-C16)/(MAX($C$2:$C$16)-MIN($C$2:$C$16))*100) -> 100 | J16: =IF(D16="","",(MAX($D$2:$D$16)-D16)/(MAX($D$2:$D$16)-MIN($D$2:$D$16))*100) -> 100 | K16: =IF(F16="","",F16) | L16: =IF(LS_Main_Dataset!X16="Committed",100,IF(LS_Main_Dataset!X16="Not Committed",40,IF(LS_Main_Dataset!X16="Not a member",15,IF(LS_Main_Dataset!X16="Not found",10,IF(LS_Main_Dataset!X16="Not Disclosed",0,""))))) -> 0 | M16: =IF(LS_Main_Dataset!AC16="Yes",100,IF(LS_Main_Dataset!AC16="No",0,"")) -> 0 | N16: =AVERAGE(G16:M16) -> 50.85 | O16: =LS_Main_Dataset!L16 -> 48.72 | P16: =IF(ISNUMBER(LS_Main_Dataset!AE16),100,IF(LS_Main_Dataset!AE16="Not Disclosed",0,"")) | Q16: =AVERAGE(O16:P16) -> 48.72 | R16: =IF(LS_Main_Dataset!G16="Public Listed",100,IF(LS_Main_Dataset!G16="Private",55,"")) -> 55 | S16: {=SUMPRODUCT(--ISNUMBER(SEARCH({"GRI","SASB","TCFD","BRSR","UNGC","Integrated Annual Report","Sustainability Report"},LS_Main_Dataset!N16)))} -> 1 | T16: =IF(S16=0,0,IF(S16=1,30,IF(S16=2,50,IF(S16=3,65,IF(S16=4,80,IF(S16=5,92,100)))))) -> 30 | U16: =IF(LS_Main_Dataset!Z16="A",100,IF(LS_Main_Dataset!Z16="A-",90,IF(LS_Main_Dataset!Z16="B",75,IF(LS_Main_Dataset!Z16="B-",65,IF(LS_Main_Dataset!Z16="C",50,IF(LS_Main_Dataset!Z16="D",25,IF(LS_Main_Dataset!Z16="Not Disclosed",0,""))))))) -> 50 | V16: =AVERAGE(T16:U16) -> 40 | W16: =N16*0.4+Q16*0.25+R16*0.2+V16*0.15 -> 49.52 | X16: =IF(W16>=90,"AAA",IF(W16>=80,"AA",IF(W16>=70,"A",IF(W16>=60,"BBB",IF(W16>=50,"BB",IF(W16>=40,"B","CCC")))))) -> B | Y16: =COUNT(G16:M16,O16:P16,R16,T16:U16)/12*100 -> 83.333333 | Z16: =IF(Y16>=80,"High",IF(Y16>=60,"Medium","Low")) -> High
